<?xml version='1.0' encoding='utf-8'?>
<robot name="for_urdf_export">
    <link name="palm">
        <inertial>
            <origin xyz="0.04408264816935304 0.021387857928123092 0.02271811661182397" rpy="0.0 0.0 0.0" />
            <mass value="1.0369816733358068" />
            <inertia ixx="0.001104979313364122" iyy="0.001031773846424572" izz="0.001706516554357987" ixy="0.00017199324393286355" iyz="9.120440866143228e-06" ixz="6.229329238586004e-06" />
        </inertial>
        <visual name="palm_visual">
            <origin xyz="0.0 0.0 0.0" rpy="0.0 0.0 0.0" />
            <geometry>
                <mesh filename="meshes/palm.stl" scale="0.001 0.001 0.001" />
            </geometry>
        </visual>
        <collision name="palm_collision">
            <origin xyz="0.0 0.0 0.0" rpy="0.0 0.0 0.0" />
            <geometry>
                <mesh filename="meshes/palm.stl" scale="0.001 0.001 0.001" />
            </geometry>
        </collision>
    </link>
    <link name="index_mcp_joint">
        <inertial>
            <origin xyz="0.02206797957377967 0.034370715917380786 0.013527985266617276" rpy="0.0 -0.0 0.0" />
            <mass value="0.22201994161036565" />
            <inertia ixx="6.410407866513186e-05" iyy="4.792197881550936e-05" izz="8.487896677913085e-05" ixy="-1.9393491168222612e-05" iyz="-1.0074778164636287e-07" ixz="1.1913147603013854e-06" />
        </inertial>
        <visual name="index_mcp_joint_visual">
            <origin xyz="-0.008406902261174415 0.007766243859716939 0.014342645014967098" rpy="-3.141592653589793 -3.7959731319666e-15 3.141592653589793" />
            <geometry>
                <mesh filename="meshes/index_mcp_joint.stl" scale="0.001 0.001 0.001" />
            </geometry>
        </visual>
        <collision name="index_mcp_joint_collision">
            <origin xyz="-0.008406902261174415 0.007766243859716939 0.014342645014967098" rpy="-3.141592653589793 -3.7959731319666e-15 3.141592653589793" />
            <geometry>
                <mesh filename="meshes/index_mcp_joint.stl" scale="0.001 0.001 0.001" />
            </geometry>
        </collision>
    </link>
    <link name="index_pip">
        <inertial>
            <origin xyz="-0.011848763937220064 -0.007984282927563867 -0.0002250070946681504" rpy="-4.3269156561887814e-63 -0.0 0.0" />
            <mass value="0.1368678994313018" />
            <inertia ixx="2.0584419662366413e-05" iyy="1.2815907211302722e-05" izz="1.850335790135136e-05" ixy="-7.976482882849511e-08" iyz="5.554241833278713e-08" ixz="-3.266596126909642e-08" />
        </inertial>
        <visual name="index_pip_visual">
            <origin xyz="0.0007840340104177735 -0.009643363092271295 -0.0003000000000002423" rpy="-3.141592653589791 6.938893903907508e-17 -1.7094033107167696e-15" />
            <geometry>
                <mesh filename="meshes/index_pip.stl" scale="0.001 0.001 0.001" />
            </geometry>
        </visual>
        <collision name="index_pip_collision">
            <origin xyz="0.0007840340104177735 -0.009643363092271295 -0.0003000000000002423" rpy="-3.141592653589791 6.938893903907508e-17 -1.7094033107167696e-15" />
            <geometry>
                <mesh filename="meshes/index_pip.stl" scale="0.001 0.001 0.001" />
            </geometry>
        </collision>
    </link>
    <link name="index_dip">
        <inertial>
            <origin xyz="0.014677740494651745 -0.030710773820957344 0.00554194187847405" rpy="0.0 -0.0 0.0" />
            <mass value="0.17326501033259323" />
            <inertia ixx="3.4657405459753016e-05" iyy="2.734143629878741e-05" izz="3.0799287255352074e-05" ixy="1.6878173640200001e-07" iyz="4.003919462593389e-06" ixz="-1.0091124470241833e-07" />
        </inertial>
        <visual name="index_dip_visual">
            <origin xyz="0.01921491183790507 -0.008432119146704756 0.021133352895225423" rpy="-3.1415926535897882 -1.5707963267948941 0" />
            <geometry>
                <mesh filename="meshes/index_dip.stl" scale="0.001 0.001 0.001" />
            </geometry>
        </visual>
        <collision name="index_dip_collision">
            <origin xyz="0.01921491183790507 -0.008432119146704756 0.021133352895225423" rpy="-3.1415926535897882 -1.5707963267948941 0" />
            <geometry>
                <mesh filename="meshes/index_dip.stl" scale="0.001 0.001 0.001" />
            </geometry>
        </collision>
    </link>
    <link name="index_fingertip">
        <inertial>
            <origin xyz="0.014499522709576294 -0.028798945208543217 -0.0010496972665653326" rpy="0.0 -0.0 0.0" />
            <mass value="0.11971825858324693" />
            <inertia ixx="2.1202943775736928e-05" iyy="1.1525224003012505e-05" izz="2.4942192418395907e-05" ixy="7.29287403036794e-11" iyz="-8.504574809062074e-07" ixz="-3.825162138661655e-10" />
        </inertial>
        <visual name="index_fingertip_visual">
            <origin xyz="0.014500000000000854 0.008885761613458226 0.013286424108534027" rpy="-3.1415926535897833 -1.5707963267948941 0" />
            <geometry>
                <mesh filename="meshes/index_fingertip.stl" scale="0.001 0.001 0.001" />
            </geometry>
        </visual>
        <collision name="index_fingertip_collision">
            <origin xyz="0.014500000000000854 0.008885761613458226 0.013286424108534027" rpy="-3.1415926535897833 -1.5707963267948941 0" />
            <geometry>
                <mesh filename="meshes/index_fingertip.stl" scale="0.001 0.001 0.001" />
            </geometry>
        </collision>
    </link>
    <link name="index_realtip">
        <inertial>
            <origin xyz="8.79296635503124e-16 -1.7763568394002506e-16 2.687387112842998e-09" rpy="0.0 -0.0 2.4274951908022974e-61" />
            <mass value="0.0005137812985558331" />
            <inertia ixx="1.2844532464210772e-09" iyy="1.284453246391431e-09" izz="1.2844532462923282e-09" ixy="-1.6940658945086007e-21" iyz="3.1763735522036263e-21" ixz="1.0587911840678754e-22" />
        </inertial>
        <visual name="index_realtip_visual">
            <origin xyz="0.007376887312613363 -0.15170000000000022 0.02040000268738656" rpy="3.141592653589792 1.5707963267948932 0" />
            <geometry>
                <mesh filename="meshes/index_realtip.stl" scale="0.001 0.001 0.001" />
            </geometry>
            <material name="ball_material">
                <color rgba="1 0 0 1"/>
            </material>
        </visual>
        <collision name="index_realtip_collision">
            <origin xyz="0.007376887312613363 -0.15170000000000022 0.02040000268738656" rpy="3.141592653589792 1.5707963267948932 0" />
            <geometry>
                <mesh filename="meshes/index_realtip.stl" scale="0.001 0.001 0.001" />
            </geometry>
        </collision>
    </link>
    <link name="middle_mcp_joint">
        <inertial>
            <origin xyz="0.02206797957377944 0.03437071591738105 0.013527985266617578" rpy="0.0 -0.0 0.0" />
            <mass value="0.22201994161036565" />
            <inertia ixx="6.410407866513045e-05" iyy="4.7921978815515433e-05" izz="8.487896677913443e-05" ixy="-1.9393491168224564e-05" iyz="-1.0074778164638959e-07" ixz="1.191314760302468e-06" />
        </inertial>
        <visual name="middle_mcp_joint_visual">
            <origin xyz="-0.008406902261174425 0.007766243859717061 0.014342645014967266" rpy="3.141592653589793 2.6897898977990595e-16 3.141592653589793" />
            <geometry>
                <mesh filename="meshes/middle_mcp_joint.stl" scale="0.001 0.001 0.001" />
            </geometry>
        </visual>
        <collision name="middle_mcp_joint_collision">
            <origin xyz="-0.008406902261174425 0.007766243859717061 0.014342645014967266" rpy="3.141592653589793 2.6897898977990595e-16 3.141592653589793" />
            <geometry>
                <mesh filename="meshes/middle_mcp_joint.stl" scale="0.001 0.001 0.001" />
            </geometry>
        </collision>
    </link>
    <link name="middle_pip">
        <inertial>
            <origin xyz="-0.011848763937220307 -0.007984282927564132 -0.0002250070946681726" rpy="-3.1761486403764e-78 -0.0 0.0" />
            <mass value="0.1368678994313018" />
            <inertia ixx="2.058441966236598e-05" iyy="1.281590721130298e-05" izz="1.8503357901351793e-05" ixy="-7.976482882833248e-08" iyz="5.554241833284134e-08" ixz="-3.2665961269191286e-08" />
        </inertial>
        <visual name="middle_pip_visual">
            <origin xyz="0.0007840340104174803 -0.009643363092271571 -0.00030000000000029114" rpy="-3.1415926535897905 2.834706814574471e-15 -1.7094033107167566e-15" />
            <geometry>
                <mesh filename="meshes/middle_pip.stl" scale="0.001 0.001 0.001" />
            </geometry>
        </visual>
        <collision name="middle_pip_collision">
            <origin xyz="0.0007840340104174803 -0.009643363092271571 -0.00030000000000029114" rpy="-3.1415926535897905 2.834706814574471e-15 -1.7094033107167566e-15" />
            <geometry>
                <mesh filename="meshes/middle_pip.stl" scale="0.001 0.001 0.001" />
            </geometry>
        </collision>
    </link>
    <link name="middle_dip">
        <inertial>
            <origin xyz="0.01467774049465128 -0.030710773820957788 0.005541941878473593" rpy="0.0 -0.0 0.0" />
            <mass value="0.17326501033259323" />
            <inertia ixx="3.465740545974998e-05" iyy="2.7341436298786326e-05" izz="3.0799287255351424e-05" ixy="1.6878173640237949e-07" iyz="4.003919462594419e-06" ixz="-1.0091124470213373e-07" />
        </inertial>
        <visual name="middle_dip_visual">
            <origin xyz="0.019214911837904844 -0.008432119146705306 0.021133352895225093" rpy="3.141592653589788 -1.5707963267948934 0" />
            <geometry>
                <mesh filename="meshes/middle_dip.stl" scale="0.001 0.001 0.001" />
            </geometry>
        </visual>
        <collision name="middle_dip_collision">
            <origin xyz="0.019214911837904844 -0.008432119146705306 0.021133352895225093" rpy="3.141592653589788 -1.5707963267948934 0" />
            <geometry>
                <mesh filename="meshes/middle_dip.stl" scale="0.001 0.001 0.001" />
            </geometry>
        </collision>
    </link>
    <link name="middle_fingertip">
        <inertial>
            <origin xyz="0.014499522709575456 -0.028798904084547595 -0.001049697266565921" rpy="0.0 -0.0 0.0" />
            <mass value="0.11971825858324643" />
            <inertia ixx="2.12032409918567e-05" iyy="1.152522400301199e-05" izz="2.494248963451611e-05" ixy="7.29263900786301e-11" iyz="-8.505280618340555e-07" ixz="-3.825162134528136e-10" />
        </inertial>
        <visual name="middle_fingertip_visual">
            <origin xyz="0.014500000000000443 -0.0061142383865422905 0.013286424108533526" rpy="3.1415926535897913 -1.570796326794893 0" />
            <geometry>
                <mesh filename="meshes/middle_fingertip.stl" scale="0.001 0.001 0.001" />
            </geometry>
        </visual>
        <collision name="middle_fingertip_collision">
            <origin xyz="0.014500000000000443 -0.0061142383865422905 0.013286424108533526" rpy="3.1415926535897913 -1.570796326794893 0" />
            <geometry>
                <mesh filename="meshes/middle_fingertip.stl" scale="0.001 0.001 0.001" />
            </geometry>
        </collision>
    </link>
    <link name="middle_realtip">
        <inertial>
            <origin xyz="-2.220446049250313e-16 2.842170943040401e-16 2.6873877478905685e-09" rpy="0.0 -0.0 0.0" />
            <mass value="0.0005137812985558314" />
            <inertia ixx="1.2844532463871959e-09" iyy="1.2844532463894723e-09" izz="1.2844532463871959e-09" ixy="-2.117582368135751e-22" iyz="-2.117582368135751e-22" ixz="2.6469779601696886e-23" />
        </inertial>
        <visual name="middle_realtip_visual">
            <origin xyz="0.007376887312612252 -0.15170000000000003 0.02040000268738729" rpy="3.1415926535897913 1.5707963267948934 0" />
            <geometry>
                <mesh filename="meshes/middle_realtip.stl" scale="0.001 0.001 0.001" />
            </geometry>
            <material name="ball_material">
                <color rgba="1 0 0 1"/>
            </material>
        </visual>
        <collision name="middle_realtip_collision">
            <origin xyz="0.007376887312612252 -0.15170000000000003 0.02040000268738729" rpy="3.1415926535897913 1.5707963267948934 0" />
            <geometry>
                <mesh filename="meshes/middle_realtip.stl" scale="0.001 0.001 0.001" />
            </geometry>
        </collision>
    </link>
    <link name="thumb_pip1">
        <inertial>
            <origin xyz="0.000225007094667804 0.007015717072435812 -0.011848763937220338" rpy="0.0 -0.0 0.0" />
            <mass value="0.1368678994313018" />
            <inertia ixx="1.850335790135125e-05" iyy="1.2815907211302397e-05" izz="2.058441966236598e-05" ixy="-5.5542418332796e-08" iyz="-7.976482882837731e-08" ixz="3.266596126911686e-08" />
        </inertial>
        <visual name="thumb_pip1_visual">
            <origin xyz="0.00030000000000002914 0.005356636907728405 0.0007840340104174449" rpy="-3.141592653589793 -1.5707963267948852 0" />
            <geometry>
                <mesh filename="meshes/thumb_pip1.stl" scale="0.001 0.001 0.001" />
            </geometry>
        </visual>
        <collision name="thumb_pip1_collision">
            <origin xyz="0.00030000000000002914 0.005356636907728405 0.0007840340104174449" rpy="-3.141592653589793 -1.5707963267948852 0" />
            <geometry>
                <mesh filename="meshes/thumb_pip1.stl" scale="0.001 0.001 0.001" />
            </geometry>
        </collision>
    </link>
    <link name="thumb_pip2">
        <inertial>
            <origin xyz="0.00692127206609797 2.4270045351215687e-09 -6.682093434129399e-10" rpy="0.0 -0.0 -1.4039453210987902e-47" />
            <mass value="0.01935609811919093" />
            <inertia ixx="4.069121186171332e-06" iyy="4.392023484606764e-06" izz="1.6616430847017248e-06" ixy="1.950074623264728e-13" iyz="6.552321163512805e-14" ixz="-5.88494638011025e-14" />
        </inertial>
        <visual name="thumb_pip2_visual">
            <origin xyz="0.015852648956663985 -0.011961920770611405 -2.531308496145357e-16" rpy="-3.1415926535897922 -1.0795345042441354e-15 -1.5707963267949083" />
            <geometry>
                <mesh filename="meshes/thumb_pip2.stl" scale="0.001 0.001 0.001" />
            </geometry>
        </visual>
        <collision name="thumb_pip2_collision">
            <origin xyz="0.015852648956663985 -0.011961920770611405 -2.531308496145357e-16" rpy="-3.1415926535897922 -1.0795345042441354e-15 -1.5707963267949083" />
            <geometry>
                <mesh filename="meshes/thumb_pip2.stl" scale="0.001 0.001 0.001" />
            </geometry>
        </collision>
    </link>
    <link name="thumb_dip">
        <inertial>
            <origin xyz="0.013377505039483744 0.0012292262844708368 -0.01403106094080699" rpy="0.0 -0.0 0.0" />
            <mass value="0.17555980876954594" />
            <inertia ixx="1.9882725828409675e-05" iyy="4.491953974664368e-05" izz="4.108519101658249e-05" ixy="-1.2625386189748632e-06" iyz="-1.8240294184549105e-07" ixz="2.4015417423564524e-07" />
        </inertial>
        <visual name="thumb_dip_visual">
            <origin xyz="0.05795295297370957 -0.043968715707238204 -0.008628676449369582" rpy="-2.0122792321332348e-16 5.504992458378667e-16 -1.5707963267948852" />
            <geometry>
                <mesh filename="meshes/thumb_dip.stl" scale="0.001 0.001 0.001" />
            </geometry>
        </visual>
        <collision name="thumb_dip_collision">
            <origin xyz="0.05795295297370957 -0.043968715707238204 -0.008628676449369582" rpy="-2.0122792321332348e-16 5.504992458378667e-16 -1.5707963267948852" />
            <geometry>
                <mesh filename="meshes/thumb_dip.stl" scale="0.001 0.001 0.001" />
            </geometry>
        </collision>
    </link>
    <link name="thumb_fingertip">
        <inertial>
            <origin xyz="0.024003654344851404 0.00035203851544702403 -0.014115004866041215" rpy="0.0 -0.0 0.0" />
            <mass value="0.25656730685939594" />
            <inertia ixx="2.3672008865558867e-05" iyy="0.00011410943092835142" izz="0.00011235777018339665" ixy="4.087395483663887e-06" iyz="-2.3556983042484322e-07" ixz="7.61370732515304e-07" />
        </inertial>
        <visual name="thumb_fingertip_visual">
            <origin xyz="-0.078459682911398 0.06255953846266743 0.048992911807332264" rpy="2.44249065417537e-15 3.683286364027454e-16 1.5707963267949079" />
            <geometry>
                <mesh filename="meshes/thumb_fingertip.stl" scale="0.001 0.001 0.001" />
            </geometry>
        </visual>
        <collision name="thumb_fingertip_collision">
            <origin xyz="-0.078459682911398 0.06255953846266743 0.048992911807332264" rpy="2.44249065417537e-15 3.683286364027454e-16 1.5707963267949079" />
            <geometry>
                <mesh filename="meshes/thumb_fingertip.stl" scale="0.001 0.001 0.001" />
            </geometry>
        </collision>
    </link>
    <link name="thumb_realtip">
        <inertial>
            <origin xyz="-2.1316282072803005e-16 -2.6873862690734997e-09 -3.508304757815495e-16" rpy="0.0 -0.0 0.0" />
            <mass value="0.0005137812985558336" />
            <inertia ixx="1.2844532463895252e-09" iyy="1.2844532463939721e-09" izz="1.284453246390584e-09" ixy="-2.665933670082917e-40" iyz="1.0587911840678754e-22" ixz="2.117582368135751e-22" />
        </inertial>
        <visual name="thumb_realtip_visual">
            <origin xyz="-0.20850000000000002 -0.05340189 -0.013500000000000002" rpy="0.0 -0.0 3.882553956340554e-31" />
            <geometry>
                <mesh filename="meshes/thumb_realtip.stl" scale="0.001 0.001 0.001" />
            </geometry>
            <material name="ball_material">
                <color rgba="1 0 0 1"/>
            </material>
        </visual>
        <collision name="thumb_realtip_collision">
            <origin xyz="-0.20850000000000002 -0.05340189 -0.013500000000000002" rpy="0.0 -0.0 3.882553956340554e-31" />
            <geometry>
                <mesh filename="meshes/thumb_realtip.stl" scale="0.001 0.001 0.001" />
            </geometry>
        </collision>
    </link>
    <joint name="palm_Revolute-1" type="continuous">
        <origin xyz="0.0637 -0.013000000000000001 0.017275000000000002" rpy="-3.141592653589793 -1.5707963267948966 0" />
        <parent link="palm" />
        <child link="index_mcp_joint" />
        <axis xyz="0.0 3.3709870223533754e-16 1.0" />
    </joint>
    <joint name="index_mcp_joint_Revolute-2" type="continuous">
        <origin xyz="0.012199999999999973 0.03810000000000001 0.014499999999999985" rpy="3.1415926535897913 3.944304526105059e-31 2.8022431570960223e-32" />
        <parent link="index_mcp_joint" />
        <child link="index_pip" />
        <axis xyz="1.0 1.0970034457409265e-32 -5.997407798921492e-16" />
    </joint>
    <joint name="index_pip_Revolute-3" type="continuous">
        <origin xyz="-0.012999999999999987 -0.015000000000000027 0.014399999999999977" rpy="-8.129871583511721e-16 1.570796326794895 0" />
        <parent link="index_pip" />
        <child link="index_dip" />
        <axis xyz="1.0 3.944304526105059e-31 1.21876284056415e-17" />
    </joint>
    <joint name="index_dip_Revolute-4" type="continuous">
        <origin xyz="9.999999999999788e-05 -0.03610000000000001 -2.886579864025407e-17" rpy="6.736023683033884e-16 -0.0 0.0" />
        <parent link="index_dip" />
        <child link="index_fingertip" />
        <axis xyz="1.0 3.9443045261050586e-31 -5.970058958597666e-16" />
    </joint>
    <joint name="index_fingertip_Rigid_index" type="fixed">
        <origin xyz="0.014499999999999994 -0.049499999999999995 -0.009098110000000006" rpy="-3.141592653589793 1.97215226305253e-31 -1.9721522630525293e-31" />
        <parent link="index_fingertip" />
        <child link="index_realtip" />
    </joint>
    <joint name="palm_Revolute-6" type="continuous">
        <origin xyz="0.005699999999999999 -0.013000000000000001 0.017275000000000002" rpy="-3.1415926535897927 -1.5707963267948966 0" />
        <parent link="palm" />
        <child link="middle_mcp_joint" />
        <axis xyz="0.0 3.9260985346659443e-16 1.0" />
    </joint>
    <joint name="middle_mcp_joint_Revolute-7" type="continuous">
        <origin xyz="0.01219999999999999 0.03810000000000001 0.014499999999999985" rpy="3.1415926535897913 2.5353555998624977e-47 6.457697323376579e-32" />
        <parent link="middle_mcp_joint" />
        <child link="middle_pip" />
        <axis xyz="1.0 -3.164352580666406e-32 -5.9974077989215e-16" />
    </joint>
    <joint name="middle_pip_Revolute-8" type="continuous">
        <origin xyz="-0.012999999999999989 -0.015000000000000027 0.014399999999999977" rpy="-8.129871583511721e-16 1.570796326794895 0" />
        <parent link="middle_pip" />
        <child link="middle_dip" />
        <axis xyz="1.0 0.0 1.21876284056415e-17" />
    </joint>
    <joint name="middle_dip_Revolute-9" type="continuous">
        <origin xyz="0.00010000000000000009 -0.03610000000000001 -2.886579864025407e-17" rpy="6.736023683033881e-16 3.944304526105061e-31 -1.9721522630525262e-31" />
        <parent link="middle_dip" />
        <child link="middle_fingertip" />
        <axis xyz="1.0 5.497760582556778e-47 -5.970058958597674e-16" />
    </joint>
    <joint name="middle_fingertip_Rigid_middle" type="fixed">
        <origin xyz="0.014499999999999996 -0.049499999999999995 -0.009098110000000006" rpy="-3.141592653589793 -2.74888029127839e-47 1.9721522630525295e-31" />
        <parent link="middle_fingertip" />
        <child link="middle_realtip" />
    </joint>
    <joint name="palm_Revolute-11" type="continuous">
        <origin xyz="0.06849999999999999 0.0495 0.0131" rpy="1.5707963267948943 -0.0 0.0" />
        <parent link="palm" />
        <child link="thumb_pip1" />
        <axis xyz="0.0 -2.2920118444087085e-15 1.0" />
    </joint>
    <joint name="thumb_pip1_Revolute-12" type="continuous">
        <origin xyz="0.01429999999999997 3.1086244689504386e-17 -0.012999999999999998" rpy="1.5707963267948981 3.944304526105086e-31 -1.2030572237243167e-30" />
        <parent link="thumb_pip1" />
        <child link="thumb_pip2" />
        <axis xyz="-1.0 1.2818309776324673e-45 -3.178737046341918e-17" />
    </joint>
    <joint name="thumb_pip2_Revolute-13" type="continuous">
        <origin xyz="0.01700000000000001 1.7763568394002505e-17 -0.014499999999999996" rpy="-3.1415926535897922 1.2030572237243175e-30 -6.767517584326818e-32" />
        <parent link="thumb_pip2" />
        <child link="thumb_dip" />
        <axis xyz="0.0 0.0 1.0" />
    </joint>
    <joint name="thumb_dip_Revolute-14" type="continuous">
        <origin xyz="0.0466 0.0 0.00020000000000000017" rpy="-1.94289029309401e-16 -0.0 -2.097380244072424e-31" />
        <parent link="thumb_dip" />
        <child link="thumb_fingertip" />
        <axis xyz="0.0 -1.94289029309401e-16 1.0" />
    </joint>
    <joint name="thumb_fingertip_Rigid_thumb" type="fixed">
        <origin xyz="0.062099999999999954 -0.009098109999999994 -0.0143" rpy="1.94289029309401e-16 1.2446602076121817e-46 -6.406229996805881e-31" />
        <parent link="thumb_fingertip" />
        <child link="thumb_realtip" />
    </joint>
</robot>